const x = 10

try {
    x = 2
} catch(err) {
    console.log(`Deu erro, se liga: ${err}`)
}

console.log("continuando o c√≥digo")